---

layout: post
categories: [Java]
tags: [Java, Exception]

---

#前言

转自[importnew](http://www.importnew.com/14688.html)

先贴个借用的代码：

```
public class TestException {
	public TestException() {
	}
	boolean testEx() throws Exception {
	boolean ret = true;
	try {
		ret = testEx1();
	} catch (Exception e) {
		System.out.println("testEx, catch exception");
		ret = false;
		throw e;
	} finally {
		System.out.println("testEx, finally; return value=" + ret);
		return ret;
		}
	}
	
	boolean testEx1() throws Exception {
	boolean ret = true;
	try {
		ret = testEx2();
		if (!ret) {
			return false;
			}
		System.out.println("testEx1, at the end of try");
		return ret;
		} catch (Exception e) {
			System.out.println("testEx1, catch exception");
			ret = false;
			throw e;
		} finally {
			System.out.println("testEx1, finally; return value=" + ret);
			return ret;
		}
	}
 
	boolean testEx2() throws Exception {
	boolean ret = true;
	try {
		int b = 12;
		int c;
		for (int i = 2; i >= -2; i--) {
		//当i=0的时候会发生exception
			c = b / i;
			System.out.println("i=" + i);
		}
		return true;
		} catch (Exception e) {
		//当i=0发生异常之后，会执行catch里的代码块
			System.out.println("testEx2, catch exception");
			ret = false;
			throw e;
		} finally {
		//执行完catch之后，
			System.out.println("testEx2, finally; return value=" + ret);
			return ret;
		}
	}
 
	public static void main(String[] args) {
		TestException testException1 = new TestException();
		try {
			testException1.testEx();
		} catch (Exception e) {
			e.printStackTrace();
		}
	}
}
```

这段代码中，非常有趣的一点是，三个finally block到底哪几个是不会被运行到的，这跟我们之前一直知道的，finally block代码不管之前的try catch结构执行情况如何都会执行的理解有一定偏差。在oracle给的doc里，有这么一句话：

`Note: If the JVM exits while the try or catch code is being executed, then the finally block may not execute. Likewise, if the thread executing the try or catch code is interrupted or killed, the finally block may not execute even though the application as a whole continues.`

在这个例子中，真实执行结果如下：

```
i=2
i=1
testEx2, catch exception
testEx2, finally; return value=false
testEx1, finally; return value=false
testEx, finally; return value=false

```
也就是说，在testEx1和testEx中，明明捕获到了Exception，却没有执行catch block里的代码，其原因，其实是在finally block里写return是一种很糟糕的办法，JVM在执行的过程中，在return前如果遇到finally，是会先执行finally中的代码，之后再去执行try-catch中的其他代码。

---

#Exception和Error

**Throwable**： 有两个重要的子类：Exception（异常）和 Error（错误），二者都是 Java 异常处理的重要子类，各自都包含大量子类。

**Error（错误）**:是程序无法处理的错误，表示运行应用程序中较严重问题。大多数错误与代码编写者执行的操作无关，而表示代码运行时 JVM（Java 虚拟机）出现的问题。例如，Java虚拟机运行错误（Virtual MachineError），当 JVM 不再有继续执行操作所需的内存资源时，将出现 OutOfMemoryError。这些异常发生时，Java虚拟机（JVM）一般会选择线程终止。

这些错误表示故障发生于虚拟机自身、或者发生在虚拟机试图执行应用时，如Java虚拟机运行错误（Virtual MachineError）、类定义错误（NoClassDefFoundError）等。这些错误是不可查的，因为它们在应用程序的控制和处理能力之外，而且绝大多数是程序运行时不允许出现的状况。对于设计合理的应用程序来说，即使确实发生了错误，本质上也不应该试图去处理它所引起的异常状况。在 Java中，错误通过Error的子类描述。

**Exception（异常）**:是程序本身可以处理的异常。

Exception 类有一个重要的子类 RuntimeException。RuntimeException 类及其子类表示“JVM 常用操作”引发的错误。例如，若试图使用空值对象引用、除数为零或数组越界，则分别引发运行时异常（NullPointerException、ArithmeticException）和 ArrayIndexOutOfBoundException。

`总之，Exception和Error之间最大的区别就在于，前者程序是可以自行处理的，后者是无法自行处理的`

此外，Exception还可以被区分为**可查异常**和**不可查异常**，除了RuntimeException及其子类以外，其他的Exception类及其子类都属于可查异常。这种异常的特点是Java编译器会检查它，也就是说，当程序中可能出现这类异常，要么用try-catch语句捕获它，要么用throws子句声明抛出它，否则编译不会通过。所以也可以分为**运行时异常**和**非运行时异常**

Java异常层次结构：

![](https://raw.githubusercontent.com/kkkelsey/kkkelsey.github.io/master/_images/150331.jpg)

---
#异常处理机制

**抛出异常**：当一个方法出现错误引发异常时，方法创建异常对象并交付运行时系统，异常对象中包含了异常类型和异常出现时的程序状态等异常信息。运行时系统负责寻找处置异常的代码并执行。

**捕获异常**：在方法抛出异常之后，运行时系统将转为寻找合适的异常处理器（exception handler）。潜在的异常处理器是异常发生时依次存留在调用栈中的方法的集合。当异常处理器所能处理的异常类型与方法抛出的异常类型相符时，即为合适 的异常处理器。运行时系统从发生异常的方法开始，依次回查调用栈中的方法，直至找到含有合适异常处理器的方法并执行。当运行时系统遍历调用栈而未找到合适 的异常处理器，则运行时系统终止。同时，意味着Java程序的终止。

###捕获异常：try-catch-finally

其中finally block不是必须的，如果没有finally，那么一般的情况是这样的：

```
try {  
    // 可能会发生异常的程序代码  
} catch (Type1 id1){  
    // 捕获并处置try抛出的异常类型Type1  
}  
catch (Type2 id2){  
     //捕获并处置try抛出的异常类型Type2  
}
……
//之后可以根据预测异常类型的不同而新增更多的catch模块

```
例子就不放了。

如果放上finally，那么就变成了：

```
try {  
    // 可能会发生异常的程序代码  
} catch (Type1 id1) {  
    // 捕获并处理try抛出的异常类型Type1  
} catch (Type2 id2) {  
    // 捕获并处理try抛出的异常类型Type2  
} finally {  
    // 无论是否发生异常，都将执行的语句块  
}
```

- try 块：用于捕获异常。其后可接零个或多个catch块，如果没有catch块，则必须跟一个finally块。
- catch 块：用于处理try捕获到的异常。
- finally 块：无论是否捕获或处理异常，finally块里的语句都会被执行。当在try块或catch块中遇到return语句时，finally语句块将在方法返回之前被执行。在以下4种特殊情况下，finally块不会被执行：


1）在finally语句块中发生了异常。

2）在前面的代码中用了System.exit()退出程序。

3）程序所在的线程死亡。

4）关闭CPU。


---
#常见异常
###runtimeException子类:

* java.lang.ArrayIndexOutOfBoundsException

    数组索引越界异常。当对数组的索引值为负数或大于等于数组大小时抛出。

* java.lang.ArithmeticException

    算术条件异常。譬如：整数除零等。

* java.lang.NullPointerException

    空指针异常。当应用试图在要求使用对象的地方使用了null时，抛出该异常。譬如：调用null对象的实例方法、访问null对象的属性、计算null对象的长度、使用throw语句抛出null等等

* java.lang.ClassNotFoundException

    找不到类异常。当应用试图根据字符串形式的类名构造类，而在遍历CLASSPAH之后找不到对应名称的class文件时，抛出该异常。

* java.lang.NegativeArraySizeException  数组长度为负异常

* java.lang.ArrayStoreException 数组中包含不兼容的值抛出的异常

* java.lang.SecurityException 安全性异常

* java.lang.IllegalArgumentException 非法参数异常


###IOException

* IOException：操作输入流和输出流时可能出现的异常。

* EOFException   文件已结束异常

* FileNotFoundException   文件未找到异常

###其他

* ClassCastException    类型转换异常类

* ArrayStoreException  数组中包含不兼容的值抛出的异常

* SQLException   操作数据库异常类

* NoSuchFieldException   字段未找到异常

* NoSuchMethodException   方法未找到抛出的异常

* NumberFormatException    字符串转换为数字抛出的异常

* StringIndexOutOfBoundsException 字符串索引超出范围抛出的异常

* IllegalAccessException  不允许访问某类异常

* InstantiationException  当应用程序试图使用Class类中的newInstance()方法创建一个类的实例，而指定的类对象无法被实例化时，抛出该异常